[2024-06-03 16:54:03,683] 181 apscheduler.scheduler - INFO -Scheduler started
[2024-06-03 16:54:06,705] 22 root - INFO -starting data ingestion
[2024-06-03 16:54:06,706] 27 root - INFO -Exporting data from casandra to feature store 
[2024-06-03 16:54:08,440] 1703 cassandra.cluster - WARNING -Downgrading core protocol version from 66 to 65 for e4d5a3c1-e93d-4762-b366-9ba2252f22f5-eu-west-1.db.astra.datastax.com:29042:00958fd0-af98-391f-9f51-7e3fe763da5c. To avoid this, it is best practice to explicitly set Cluster(protocol_version) to the version supported by your cluster. http://datastax.github.io/python-driver/api/cassandra/cluster.html#cassandra.cluster.Cluster.protocol_version
[2024-06-03 16:54:09,787] 1703 cassandra.cluster - WARNING -Downgrading core protocol version from 65 to 5 for e4d5a3c1-e93d-4762-b366-9ba2252f22f5-eu-west-1.db.astra.datastax.com:29042:00958fd0-af98-391f-9f51-7e3fe763da5c. To avoid this, it is best practice to explicitly set Cluster(protocol_version) to the version supported by your cluster. http://datastax.github.io/python-driver/api/cassandra/cluster.html#cassandra.cluster.Cluster.protocol_version
[2024-06-03 16:54:11,373] 1703 cassandra.cluster - WARNING -Downgrading core protocol version from 5 to 4 for e4d5a3c1-e93d-4762-b366-9ba2252f22f5-eu-west-1.db.astra.datastax.com:29042:00958fd0-af98-391f-9f51-7e3fe763da5c. To avoid this, it is best practice to explicitly set Cluster(protocol_version) to the version supported by your cluster. http://datastax.github.io/python-driver/api/cassandra/cluster.html#cassandra.cluster.Cluster.protocol_version
[2024-06-03 16:54:14,333] 292 cassandra.policies - INFO -Using datacenter 'eu-west-1' for DCAwareRoundRobinPolicy (via host 'e4d5a3c1-e93d-4762-b366-9ba2252f22f5-eu-west-1.db.astra.datastax.com:29042:00958fd0-af98-391f-9f51-7e3fe763da5c'); if incorrect, please specify a local_dc to the constructor, or limit contact points to local cluster nodes
[2024-06-03 16:54:14,334] 3863 cassandra.cluster - WARNING -Found multiple hosts with the same endpoint (e4d5a3c1-e93d-4762-b366-9ba2252f22f5-eu-west-1.db.astra.datastax.com:29042:00958fd0-af98-391f-9f51-7e3fe763da5c). Excluding peer 10.0.0.7
[2024-06-03 16:54:14,334] 2126 cassandra.cluster - INFO -Cassandra host e4d5a3c1-e93d-4762-b366-9ba2252f22f5-eu-west-1.db.astra.datastax.com:29042:00694036-11ec-39fb-8238-d79afd9b0e46 removed
[2024-06-03 16:54:21,161] 36 root - INFO -artifact-datainjection folder created 
[2024-06-03 16:54:21,224] 45 root - INFO -performed train test split on dataframe
[2024-06-03 16:54:21,224] 46 root - INFO -exited split_data as train test split
[2024-06-03 16:54:21,225] 51 root - INFO -exporting train and test file path
[2024-06-03 16:54:21,280] 56 root - INFO -exported train and test file path
[2024-06-03 16:54:21,281] 26 root - INFO -Data ingestion completed and artifact
[2024-06-03 16:54:21,281] 27 root - INFO -Data ingestion completed and artifact: DataIngestionArtifact(trained_file_path='artifact\\06_03_2024_16_53_57\\data_ingestion\\ingested\\train.csv')
[2024-06-03 16:54:21,383] 25 root - INFO -Required number of columns: 5
[2024-06-03 16:54:21,383] 26 root - INFO -Data frame has columns: 5
[2024-06-03 16:54:21,383] 45 root - INFO -Missing numerical columns: [[]]
[2024-06-03 16:54:21,383] 133 root - INFO -Data validation artifact: DataValidationArtifact(validation_status=True, valid_train_file_path='artifact\\06_03_2024_16_53_57\\data_ingestion\\ingested\\train.csv', invalid_train_file_path=None, invalid_test_file_path=None, drift_report_file_path='artifact\\06_03_2024_16_53_57\\data_validation\\drift_report\\report.yaml')
[2024-06-03 16:54:23,111] 41 root - ERROR -Error occurred python script name [C:\Users\DELL\PycharmProjects\pythonProject5\src\pipeline\training_pipeline.py] line number [63] error message [Error occurred python script name [C:\Users\DELL\PycharmProjects\pythonProject5\src\pipeline\training_pipeline.py] line number [50] error message [Error occurred python script name [C:\Users\DELL\PycharmProjects\pythonProject5\src\components\data_transformation.py] line number [143] error message ['DateTime']]]
Traceback (most recent call last):
  File "C:\Users\DELL\anaconda3\envs\pythonProject5\lib\site-packages\pandas\core\indexes\base.py", line 3361, in get_loc
    return self._engine.get_loc(casted_key)
  File "pandas\_libs\index.pyx", line 76, in pandas._libs.index.IndexEngine.get_loc
  File "pandas\_libs\index.pyx", line 108, in pandas._libs.index.IndexEngine.get_loc
  File "pandas\_libs\hashtable_class_helper.pxi", line 5198, in pandas._libs.hashtable.PyObjectHashTable.get_item
  File "pandas\_libs\hashtable_class_helper.pxi", line 5206, in pandas._libs.hashtable.PyObjectHashTable.get_item
KeyError: 'DateTime'

The above exception was the direct cause of the following exception:

Traceback (most recent call last):
  File "C:\Users\DELL\PycharmProjects\pythonProject5\src\components\data_transformation.py", line 143, in initiate_data_transformation
    result_df33['NumericTimestamp1'] = result_df33['DateTime'].apply(lambda x: datetime.strptime(x, date_format).timestamp())
  File "C:\Users\DELL\anaconda3\envs\pythonProject5\lib\site-packages\pandas\core\frame.py", line 3458, in __getitem__
    indexer = self.columns.get_loc(key)
  File "C:\Users\DELL\anaconda3\envs\pythonProject5\lib\site-packages\pandas\core\indexes\base.py", line 3363, in get_loc
    raise KeyError(key) from err
KeyError: 'DateTime'

The above exception was the direct cause of the following exception:

Traceback (most recent call last):
  File "C:\Users\DELL\PycharmProjects\pythonProject5\src\pipeline\training_pipeline.py", line 50, in start_data_transformation
    data_transformation_artifact =  data_transformation.initiate_data_transformation()
  File "C:\Users\DELL\PycharmProjects\pythonProject5\src\components\data_transformation.py", line 226, in initiate_data_transformation
    raise SensorException(e, sys) from e
src.exception.SensorException: Error occurred python script name [C:\Users\DELL\PycharmProjects\pythonProject5\src\components\data_transformation.py] line number [143] error message ['DateTime']

During handling of the above exception, another exception occurred:

Traceback (most recent call last):
  File "C:\Users\DELL\PycharmProjects\pythonProject5\src\pipeline\training_pipeline.py", line 63, in run_pipeline
    data_validation_artifact=data_validation_artifact)
  File "C:\Users\DELL\PycharmProjects\pythonProject5\src\pipeline\training_pipeline.py", line 53, in start_data_transformation
    raise  SensorException(e,sys)
src.exception.SensorException: Error occurred python script name [C:\Users\DELL\PycharmProjects\pythonProject5\src\pipeline\training_pipeline.py] line number [50] error message [Error occurred python script name [C:\Users\DELL\PycharmProjects\pythonProject5\src\components\data_transformation.py] line number [143] error message ['DateTime']]

During handling of the above exception, another exception occurred:

Traceback (most recent call last):
  File "main.py", line 37, in trainRouteClient
    train_pipeline.run_pipeline()
  File "C:\Users\DELL\PycharmProjects\pythonProject5\src\pipeline\training_pipeline.py", line 66, in run_pipeline
    raise SensorException(e, sys)
src.exception.SensorException: Error occurred python script name [C:\Users\DELL\PycharmProjects\pythonProject5\src\pipeline\training_pipeline.py] line number [63] error message [Error occurred python script name [C:\Users\DELL\PycharmProjects\pythonProject5\src\pipeline\training_pipeline.py] line number [50] error message [Error occurred python script name [C:\Users\DELL\PycharmProjects\pythonProject5\src\components\data_transformation.py] line number [143] error message ['DateTime']]]
[2024-06-03 16:54:23,133] 1745 main - ERROR -Exception on /train [GET]
Traceback (most recent call last):
  File "C:\Users\DELL\anaconda3\envs\pythonProject5\lib\site-packages\flask\app.py", line 2529, in wsgi_app
    response = self.full_dispatch_request()
  File "C:\Users\DELL\anaconda3\envs\pythonProject5\lib\site-packages\flask\app.py", line 1825, in full_dispatch_request
    rv = self.handle_user_exception(e)
  File "C:\Users\DELL\anaconda3\envs\pythonProject5\lib\site-packages\flask_cors\extension.py", line 178, in wrapped_function
    return cors_after_request(app.make_response(f(*args, **kwargs)))
  File "C:\Users\DELL\anaconda3\envs\pythonProject5\lib\site-packages\flask\app.py", line 1823, in full_dispatch_request
    rv = self.dispatch_request()
  File "C:\Users\DELL\anaconda3\envs\pythonProject5\lib\site-packages\flask\app.py", line 1799, in dispatch_request
    return self.ensure_sync(self.view_functions[rule.endpoint])(**view_args)
  File "C:\Users\DELL\anaconda3\envs\pythonProject5\lib\site-packages\flask_cors\decorator.py", line 130, in wrapped_function
    resp = make_response(f(*args, **kwargs))
  File "C:\Users\DELL\anaconda3\envs\pythonProject5\lib\site-packages\flask\helpers.py", line 209, in make_response
    return current_app.make_response(args)  # type: ignore
  File "C:\Users\DELL\anaconda3\envs\pythonProject5\lib\site-packages\flask\app.py", line 2139, in make_response
    f"The view function for {request.endpoint!r} did not"
TypeError: The view function for 'trainRouteClient' did not return a valid response. The function either returned None or ended without a return statement.
[2024-06-03 17:56:05,955] 1734 cassandra.connection - WARNING -Heartbeat failed for connection (2126291325576) to e4d5a3c1-e93d-4762-b366-9ba2252f22f5-eu-west-1.db.astra.datastax.com:29042:678e6a1d-e5b1-3cba-b949-7bfaf823957f
[2024-06-03 17:56:05,964] 1734 cassandra.connection - WARNING -Heartbeat failed for connection (2126291182408) to e4d5a3c1-e93d-4762-b366-9ba2252f22f5-eu-west-1.db.astra.datastax.com:29042:0750e59f-441b-37bb-b0a7-e097c5d725f7
[2024-06-03 17:56:05,964] 1734 cassandra.connection - WARNING -Heartbeat failed for connection (2126291581064) to e4d5a3c1-e93d-4762-b366-9ba2252f22f5-eu-west-1.db.astra.datastax.com:29042:b4f6d9ed-0f1d-3f7a-82f1-a4a7ea4f84d4
[2024-06-03 17:56:05,965] 1734 cassandra.connection - WARNING -Heartbeat failed for connection (2126291582344) to e4d5a3c1-e93d-4762-b366-9ba2252f22f5-eu-west-1.db.astra.datastax.com:29042:00958fd0-af98-391f-9f51-7e3fe763da5c
[2024-06-03 17:56:05,965] 1734 cassandra.connection - WARNING -Heartbeat failed for connection (2126291595720) to e4d5a3c1-e93d-4762-b366-9ba2252f22f5-eu-west-1.db.astra.datastax.com:29042:0669df0f-031f-383e-b452-67a9679bbc6a
[2024-06-03 17:56:05,965] 1734 cassandra.connection - WARNING -Heartbeat failed for connection (2126291597960) to e4d5a3c1-e93d-4762-b366-9ba2252f22f5-eu-west-1.db.astra.datastax.com:29042:98a2cd7e-fa1b-3950-942e-42af495c4248
[2024-06-03 17:56:05,965] 1734 cassandra.connection - WARNING -Heartbeat failed for connection (2126291633160) to e4d5a3c1-e93d-4762-b366-9ba2252f22f5-eu-west-1.db.astra.datastax.com:29042:9e3a5bee-3d95-3bf7-90f5-09bd2177324b
[2024-06-03 17:56:06,327] 1734 cassandra.connection - WARNING -Heartbeat failed for connection (2126291633736) to e4d5a3c1-e93d-4762-b366-9ba2252f22f5-eu-west-1.db.astra.datastax.com:29042:190dafab-6970-3a67-a21c-1226360de7dc
[2024-06-03 17:56:06,328] 1734 cassandra.connection - WARNING -Heartbeat failed for connection (2126291129288) to e4d5a3c1-e93d-4762-b366-9ba2252f22f5-eu-west-1.db.astra.datastax.com:29042:00958fd0-af98-391f-9f51-7e3fe763da5c
[2024-06-03 17:56:06,352] 2000 cassandra.cluster - WARNING -Host e4d5a3c1-e93d-4762-b366-9ba2252f22f5-eu-west-1.db.astra.datastax.com:29042:678e6a1d-e5b1-3cba-b949-7bfaf823957f has been marked down
[2024-06-03 17:56:06,359] 2000 cassandra.cluster - WARNING -Host e4d5a3c1-e93d-4762-b366-9ba2252f22f5-eu-west-1.db.astra.datastax.com:29042:0750e59f-441b-37bb-b0a7-e097c5d725f7 has been marked down
[2024-06-03 17:56:06,360] 2000 cassandra.cluster - WARNING -Host e4d5a3c1-e93d-4762-b366-9ba2252f22f5-eu-west-1.db.astra.datastax.com:29042:b4f6d9ed-0f1d-3f7a-82f1-a4a7ea4f84d4 has been marked down
[2024-06-03 17:56:06,361] 2000 cassandra.cluster - WARNING -Host e4d5a3c1-e93d-4762-b366-9ba2252f22f5-eu-west-1.db.astra.datastax.com:29042:00958fd0-af98-391f-9f51-7e3fe763da5c has been marked down
[2024-06-03 17:56:06,362] 2000 cassandra.cluster - WARNING -Host e4d5a3c1-e93d-4762-b366-9ba2252f22f5-eu-west-1.db.astra.datastax.com:29042:0669df0f-031f-383e-b452-67a9679bbc6a has been marked down
[2024-06-03 17:56:06,362] 2000 cassandra.cluster - WARNING -Host e4d5a3c1-e93d-4762-b366-9ba2252f22f5-eu-west-1.db.astra.datastax.com:29042:98a2cd7e-fa1b-3950-942e-42af495c4248 has been marked down
[2024-06-03 17:56:06,363] 2000 cassandra.cluster - WARNING -Host e4d5a3c1-e93d-4762-b366-9ba2252f22f5-eu-west-1.db.astra.datastax.com:29042:9e3a5bee-3d95-3bf7-90f5-09bd2177324b has been marked down
[2024-06-03 17:56:06,364] 2000 cassandra.cluster - WARNING -Host e4d5a3c1-e93d-4762-b366-9ba2252f22f5-eu-west-1.db.astra.datastax.com:29042:190dafab-6970-3a67-a21c-1226360de7dc has been marked down
[2024-06-03 17:56:09,111] 2115 cassandra.cluster - INFO -New Cassandra host <Host: e4d5a3c1-e93d-4762-b366-9ba2252f22f5-eu-west-1.db.astra.datastax.com:29042:00694036-11ec-39fb-8238-d79afd9b0e46 eu-west-1> discovered
[2024-06-03 17:56:09,902] 352 cassandra.pool - INFO -Successful reconnection to e4d5a3c1-e93d-4762-b366-9ba2252f22f5-eu-west-1.db.astra.datastax.com:29042:678e6a1d-e5b1-3cba-b949-7bfaf823957f, marking node up if it isn't already
[2024-06-03 17:56:09,903] 1900 cassandra.cluster - INFO -Host e4d5a3c1-e93d-4762-b366-9ba2252f22f5-eu-west-1.db.astra.datastax.com:29042:678e6a1d-e5b1-3cba-b949-7bfaf823957f may be up; will prepare queries and open connection pool
[2024-06-03 17:56:11,767] 352 cassandra.pool - INFO -Successful reconnection to e4d5a3c1-e93d-4762-b366-9ba2252f22f5-eu-west-1.db.astra.datastax.com:29042:0750e59f-441b-37bb-b0a7-e097c5d725f7, marking node up if it isn't already
[2024-06-03 17:56:11,768] 1900 cassandra.cluster - INFO -Host e4d5a3c1-e93d-4762-b366-9ba2252f22f5-eu-west-1.db.astra.datastax.com:29042:0750e59f-441b-37bb-b0a7-e097c5d725f7 may be up; will prepare queries and open connection pool
[2024-06-03 17:56:13,006] 352 cassandra.pool - INFO -Successful reconnection to e4d5a3c1-e93d-4762-b366-9ba2252f22f5-eu-west-1.db.astra.datastax.com:29042:b4f6d9ed-0f1d-3f7a-82f1-a4a7ea4f84d4, marking node up if it isn't already
[2024-06-03 17:56:13,006] 1900 cassandra.cluster - INFO -Host e4d5a3c1-e93d-4762-b366-9ba2252f22f5-eu-west-1.db.astra.datastax.com:29042:b4f6d9ed-0f1d-3f7a-82f1-a4a7ea4f84d4 may be up; will prepare queries and open connection pool
[2024-06-03 17:56:14,521] 352 cassandra.pool - INFO -Successful reconnection to e4d5a3c1-e93d-4762-b366-9ba2252f22f5-eu-west-1.db.astra.datastax.com:29042:0669df0f-031f-383e-b452-67a9679bbc6a, marking node up if it isn't already
[2024-06-03 17:56:14,522] 1900 cassandra.cluster - INFO -Host e4d5a3c1-e93d-4762-b366-9ba2252f22f5-eu-west-1.db.astra.datastax.com:29042:0669df0f-031f-383e-b452-67a9679bbc6a may be up; will prepare queries and open connection pool
[2024-06-03 17:56:14,637] 352 cassandra.pool - INFO -Successful reconnection to e4d5a3c1-e93d-4762-b366-9ba2252f22f5-eu-west-1.db.astra.datastax.com:29042:98a2cd7e-fa1b-3950-942e-42af495c4248, marking node up if it isn't already
[2024-06-03 17:56:14,637] 1900 cassandra.cluster - INFO -Host e4d5a3c1-e93d-4762-b366-9ba2252f22f5-eu-west-1.db.astra.datastax.com:29042:98a2cd7e-fa1b-3950-942e-42af495c4248 may be up; will prepare queries and open connection pool
[2024-06-03 17:56:15,914] 352 cassandra.pool - INFO -Successful reconnection to e4d5a3c1-e93d-4762-b366-9ba2252f22f5-eu-west-1.db.astra.datastax.com:29042:9e3a5bee-3d95-3bf7-90f5-09bd2177324b, marking node up if it isn't already
[2024-06-03 17:56:15,914] 1900 cassandra.cluster - INFO -Host e4d5a3c1-e93d-4762-b366-9ba2252f22f5-eu-west-1.db.astra.datastax.com:29042:9e3a5bee-3d95-3bf7-90f5-09bd2177324b may be up; will prepare queries and open connection pool
[2024-06-03 17:56:16,025] 352 cassandra.pool - INFO -Successful reconnection to e4d5a3c1-e93d-4762-b366-9ba2252f22f5-eu-west-1.db.astra.datastax.com:29042:190dafab-6970-3a67-a21c-1226360de7dc, marking node up if it isn't already
[2024-06-03 17:56:16,025] 1900 cassandra.cluster - INFO -Host e4d5a3c1-e93d-4762-b366-9ba2252f22f5-eu-west-1.db.astra.datastax.com:29042:190dafab-6970-3a67-a21c-1226360de7dc may be up; will prepare queries and open connection pool
[2024-06-03 17:56:17,347] 352 cassandra.pool - INFO -Successful reconnection to e4d5a3c1-e93d-4762-b366-9ba2252f22f5-eu-west-1.db.astra.datastax.com:29042:00958fd0-af98-391f-9f51-7e3fe763da5c, marking node up if it isn't already
[2024-06-03 17:56:17,348] 1900 cassandra.cluster - INFO -Host e4d5a3c1-e93d-4762-b366-9ba2252f22f5-eu-west-1.db.astra.datastax.com:29042:00958fd0-af98-391f-9f51-7e3fe763da5c may be up; will prepare queries and open connection pool
[2024-06-03 17:56:17,992] 3863 cassandra.cluster - WARNING -Found multiple hosts with the same endpoint (e4d5a3c1-e93d-4762-b366-9ba2252f22f5-eu-west-1.db.astra.datastax.com:29042:0750e59f-441b-37bb-b0a7-e097c5d725f7). Excluding peer 10.0.0.8
[2024-06-03 17:56:17,992] 2126 cassandra.cluster - INFO -Cassandra host e4d5a3c1-e93d-4762-b366-9ba2252f22f5-eu-west-1.db.astra.datastax.com:29042:98a2cd7e-fa1b-3950-942e-42af495c4248 removed
[2024-06-03 17:56:18,486] 2115 cassandra.cluster - INFO -New Cassandra host <Host: e4d5a3c1-e93d-4762-b366-9ba2252f22f5-eu-west-1.db.astra.datastax.com:29042:98a2cd7e-fa1b-3950-942e-42af495c4248 eu-west-1> discovered
[2024-06-03 17:56:21,646] 1864 cassandra.cluster - INFO -Connection pools established for node e4d5a3c1-e93d-4762-b366-9ba2252f22f5-eu-west-1.db.astra.datastax.com:29042:678e6a1d-e5b1-3cba-b949-7bfaf823957f
[2024-06-03 17:56:21,653] 1864 cassandra.cluster - INFO -Connection pools established for node e4d5a3c1-e93d-4762-b366-9ba2252f22f5-eu-west-1.db.astra.datastax.com:29042:0750e59f-441b-37bb-b0a7-e097c5d725f7
[2024-06-03 17:56:24,594] 1864 cassandra.cluster - INFO -Connection pools established for node e4d5a3c1-e93d-4762-b366-9ba2252f22f5-eu-west-1.db.astra.datastax.com:29042:b4f6d9ed-0f1d-3f7a-82f1-a4a7ea4f84d4
[2024-06-03 17:56:24,667] 1864 cassandra.cluster - INFO -Connection pools established for node e4d5a3c1-e93d-4762-b366-9ba2252f22f5-eu-west-1.db.astra.datastax.com:29042:0669df0f-031f-383e-b452-67a9679bbc6a
[2024-06-03 17:56:27,564] 1864 cassandra.cluster - INFO -Connection pools established for node e4d5a3c1-e93d-4762-b366-9ba2252f22f5-eu-west-1.db.astra.datastax.com:29042:9e3a5bee-3d95-3bf7-90f5-09bd2177324b
[2024-06-03 17:56:27,600] 1864 cassandra.cluster - INFO -Connection pools established for node e4d5a3c1-e93d-4762-b366-9ba2252f22f5-eu-west-1.db.astra.datastax.com:29042:98a2cd7e-fa1b-3950-942e-42af495c4248
[2024-06-03 17:56:30,384] 1864 cassandra.cluster - INFO -Connection pools established for node e4d5a3c1-e93d-4762-b366-9ba2252f22f5-eu-west-1.db.astra.datastax.com:29042:190dafab-6970-3a67-a21c-1226360de7dc
[2024-06-03 17:56:30,434] 1864 cassandra.cluster - INFO -Connection pools established for node e4d5a3c1-e93d-4762-b366-9ba2252f22f5-eu-west-1.db.astra.datastax.com:29042:00958fd0-af98-391f-9f51-7e3fe763da5c
[2024-06-03 17:56:49,112] 3863 cassandra.cluster - WARNING -Found multiple hosts with the same endpoint (e4d5a3c1-e93d-4762-b366-9ba2252f22f5-eu-west-1.db.astra.datastax.com:29042:b4f6d9ed-0f1d-3f7a-82f1-a4a7ea4f84d4). Excluding peer 10.0.0.9
[2024-06-03 17:56:49,112] 2126 cassandra.cluster - INFO -Cassandra host e4d5a3c1-e93d-4762-b366-9ba2252f22f5-eu-west-1.db.astra.datastax.com:29042:00694036-11ec-39fb-8238-d79afd9b0e46 removed
[2024-06-03 17:56:51,432] 3863 cassandra.cluster - WARNING -Found multiple hosts with the same endpoint (e4d5a3c1-e93d-4762-b366-9ba2252f22f5-eu-west-1.db.astra.datastax.com:29042:98a2cd7e-fa1b-3950-942e-42af495c4248). Excluding peer 10.0.0.2
[2024-06-03 17:56:51,433] 2115 cassandra.cluster - INFO -New Cassandra host <Host: e4d5a3c1-e93d-4762-b366-9ba2252f22f5-eu-west-1.db.astra.datastax.com:29042:00694036-11ec-39fb-8238-d79afd9b0e46 eu-west-1> discovered
[2024-06-03 17:56:51,434] 2126 cassandra.cluster - INFO -Cassandra host e4d5a3c1-e93d-4762-b366-9ba2252f22f5-eu-west-1.db.astra.datastax.com:29042:00958fd0-af98-391f-9f51-7e3fe763da5c removed
[2024-06-03 17:56:51,993] 2115 cassandra.cluster - INFO -New Cassandra host <Host: e4d5a3c1-e93d-4762-b366-9ba2252f22f5-eu-west-1.db.astra.datastax.com:29042:00958fd0-af98-391f-9f51-7e3fe763da5c eu-west-1> discovered
[2024-06-03 17:56:51,994] 3863 cassandra.cluster - WARNING -Found multiple hosts with the same endpoint (e4d5a3c1-e93d-4762-b366-9ba2252f22f5-eu-west-1.db.astra.datastax.com:29042:b4f6d9ed-0f1d-3f7a-82f1-a4a7ea4f84d4). Excluding peer 10.0.0.9
[2024-06-03 17:56:51,994] 2126 cassandra.cluster - INFO -Cassandra host e4d5a3c1-e93d-4762-b366-9ba2252f22f5-eu-west-1.db.astra.datastax.com:29042:00694036-11ec-39fb-8238-d79afd9b0e46 removed
[2024-06-03 17:56:52,496] 3863 cassandra.cluster - WARNING -Found multiple hosts with the same endpoint (e4d5a3c1-e93d-4762-b366-9ba2252f22f5-eu-west-1.db.astra.datastax.com:29042:b4f6d9ed-0f1d-3f7a-82f1-a4a7ea4f84d4). Excluding peer 10.0.0.9
[2024-06-03 18:08:06,237] 1734 cassandra.connection - WARNING -Heartbeat failed for connection (2126291354312) to e4d5a3c1-e93d-4762-b366-9ba2252f22f5-eu-west-1.db.astra.datastax.com:29042:98a2cd7e-fa1b-3950-942e-42af495c4248
[2024-06-03 18:08:10,998] 3584 cassandra.cluster - WARNING -[control connection] Error connecting to e4d5a3c1-e93d-4762-b366-9ba2252f22f5-eu-west-1.db.astra.datastax.com:29042:98a2cd7e-fa1b-3950-942e-42af495c4248:
Traceback (most recent call last):
  File "C:\Users\DELL\anaconda3\envs\pythonProject5\lib\site-packages\cassandra\cluster.py", line 3577, in _reconnect_internal
    return self._try_connect(host)
  File "C:\Users\DELL\anaconda3\envs\pythonProject5\lib\site-packages\cassandra\cluster.py", line 3599, in _try_connect
    connection = self._cluster.connection_factory(host.endpoint, is_control_connection=True)
  File "C:\Users\DELL\anaconda3\envs\pythonProject5\lib\site-packages\cassandra\cluster.py", line 1670, in connection_factory
    return self.connection_class.factory(endpoint, self.connect_timeout, *args, **kwargs)
  File "C:\Users\DELL\anaconda3\envs\pythonProject5\lib\site-packages\cassandra\connection.py", line 846, in factory
    conn = cls(endpoint, *args, **kwargs)
  File "C:\Users\DELL\anaconda3\envs\pythonProject5\lib\site-packages\cassandra\io\asyncorereactor.py", line 354, in __init__
    self._connect_socket()
  File "C:\Users\DELL\anaconda3\envs\pythonProject5\lib\site-packages\cassandra\connection.py", line 925, in _connect_socket
    addresses = self._get_socket_addresses()
  File "C:\Users\DELL\anaconda3\envs\pythonProject5\lib\site-packages\cassandra\connection.py", line 912, in _get_socket_addresses
    address, port = self.endpoint.resolve()
  File "C:\Users\DELL\anaconda3\envs\pythonProject5\lib\site-packages\cassandra\connection.py", line 271, in resolve
    socket.AF_UNSPEC, socket.SOCK_STREAM)
  File "C:\Users\DELL\anaconda3\envs\pythonProject5\lib\socket.py", line 752, in getaddrinfo
    for res in _socket.getaddrinfo(host, port, family, type, proto, flags):
socket.gaierror: [Errno 11001] getaddrinfo failed
[2024-06-03 18:08:19,028] 3584 cassandra.cluster - WARNING -[control connection] Error connecting to e4d5a3c1-e93d-4762-b366-9ba2252f22f5-eu-west-1.db.astra.datastax.com:29042:00958fd0-af98-391f-9f51-7e3fe763da5c:
Traceback (most recent call last):
  File "C:\Users\DELL\anaconda3\envs\pythonProject5\lib\site-packages\cassandra\cluster.py", line 3577, in _reconnect_internal
    return self._try_connect(host)
  File "C:\Users\DELL\anaconda3\envs\pythonProject5\lib\site-packages\cassandra\cluster.py", line 3599, in _try_connect
    connection = self._cluster.connection_factory(host.endpoint, is_control_connection=True)
  File "C:\Users\DELL\anaconda3\envs\pythonProject5\lib\site-packages\cassandra\cluster.py", line 1670, in connection_factory
    return self.connection_class.factory(endpoint, self.connect_timeout, *args, **kwargs)
  File "C:\Users\DELL\anaconda3\envs\pythonProject5\lib\site-packages\cassandra\connection.py", line 846, in factory
    conn = cls(endpoint, *args, **kwargs)
  File "C:\Users\DELL\anaconda3\envs\pythonProject5\lib\site-packages\cassandra\io\asyncorereactor.py", line 354, in __init__
    self._connect_socket()
  File "C:\Users\DELL\anaconda3\envs\pythonProject5\lib\site-packages\cassandra\connection.py", line 925, in _connect_socket
    addresses = self._get_socket_addresses()
  File "C:\Users\DELL\anaconda3\envs\pythonProject5\lib\site-packages\cassandra\connection.py", line 912, in _get_socket_addresses
    address, port = self.endpoint.resolve()
  File "C:\Users\DELL\anaconda3\envs\pythonProject5\lib\site-packages\cassandra\connection.py", line 271, in resolve
    socket.AF_UNSPEC, socket.SOCK_STREAM)
  File "C:\Users\DELL\anaconda3\envs\pythonProject5\lib\socket.py", line 752, in getaddrinfo
    for res in _socket.getaddrinfo(host, port, family, type, proto, flags):
socket.gaierror: [Errno 11001] getaddrinfo failed
[2024-06-03 18:08:19,029] 3584 cassandra.cluster - WARNING -[control connection] Error connecting to e4d5a3c1-e93d-4762-b366-9ba2252f22f5-eu-west-1.db.astra.datastax.com:29042:00958fd0-af98-391f-9f51-7e3fe763da5c:
Traceback (most recent call last):
  File "C:\Users\DELL\anaconda3\envs\pythonProject5\lib\site-packages\cassandra\cluster.py", line 3577, in _reconnect_internal
    return self._try_connect(host)
  File "C:\Users\DELL\anaconda3\envs\pythonProject5\lib\site-packages\cassandra\cluster.py", line 3599, in _try_connect
    connection = self._cluster.connection_factory(host.endpoint, is_control_connection=True)
  File "C:\Users\DELL\anaconda3\envs\pythonProject5\lib\site-packages\cassandra\cluster.py", line 1670, in connection_factory
    return self.connection_class.factory(endpoint, self.connect_timeout, *args, **kwargs)
  File "C:\Users\DELL\anaconda3\envs\pythonProject5\lib\site-packages\cassandra\connection.py", line 846, in factory
    conn = cls(endpoint, *args, **kwargs)
  File "C:\Users\DELL\anaconda3\envs\pythonProject5\lib\site-packages\cassandra\io\asyncorereactor.py", line 354, in __init__
    self._connect_socket()
  File "C:\Users\DELL\anaconda3\envs\pythonProject5\lib\site-packages\cassandra\connection.py", line 925, in _connect_socket
    addresses = self._get_socket_addresses()
  File "C:\Users\DELL\anaconda3\envs\pythonProject5\lib\site-packages\cassandra\connection.py", line 912, in _get_socket_addresses
    address, port = self.endpoint.resolve()
  File "C:\Users\DELL\anaconda3\envs\pythonProject5\lib\site-packages\cassandra\connection.py", line 271, in resolve
    socket.AF_UNSPEC, socket.SOCK_STREAM)
  File "C:\Users\DELL\anaconda3\envs\pythonProject5\lib\socket.py", line 752, in getaddrinfo
    for res in _socket.getaddrinfo(host, port, family, type, proto, flags):
socket.gaierror: [Errno 11001] getaddrinfo failed
[2024-06-03 18:08:19,031] 3584 cassandra.cluster - WARNING -[control connection] Error connecting to e4d5a3c1-e93d-4762-b366-9ba2252f22f5-eu-west-1.db.astra.datastax.com:29042:678e6a1d-e5b1-3cba-b949-7bfaf823957f:
Traceback (most recent call last):
  File "C:\Users\DELL\anaconda3\envs\pythonProject5\lib\site-packages\cassandra\cluster.py", line 3577, in _reconnect_internal
    return self._try_connect(host)
  File "C:\Users\DELL\anaconda3\envs\pythonProject5\lib\site-packages\cassandra\cluster.py", line 3599, in _try_connect
    connection = self._cluster.connection_factory(host.endpoint, is_control_connection=True)
  File "C:\Users\DELL\anaconda3\envs\pythonProject5\lib\site-packages\cassandra\cluster.py", line 1670, in connection_factory
    return self.connection_class.factory(endpoint, self.connect_timeout, *args, **kwargs)
  File "C:\Users\DELL\anaconda3\envs\pythonProject5\lib\site-packages\cassandra\connection.py", line 846, in factory
    conn = cls(endpoint, *args, **kwargs)
  File "C:\Users\DELL\anaconda3\envs\pythonProject5\lib\site-packages\cassandra\io\asyncorereactor.py", line 354, in __init__
    self._connect_socket()
  File "C:\Users\DELL\anaconda3\envs\pythonProject5\lib\site-packages\cassandra\connection.py", line 925, in _connect_socket
    addresses = self._get_socket_addresses()
  File "C:\Users\DELL\anaconda3\envs\pythonProject5\lib\site-packages\cassandra\connection.py", line 912, in _get_socket_addresses
    address, port = self.endpoint.resolve()
  File "C:\Users\DELL\anaconda3\envs\pythonProject5\lib\site-packages\cassandra\connection.py", line 271, in resolve
    socket.AF_UNSPEC, socket.SOCK_STREAM)
  File "C:\Users\DELL\anaconda3\envs\pythonProject5\lib\socket.py", line 752, in getaddrinfo
    for res in _socket.getaddrinfo(host, port, family, type, proto, flags):
socket.gaierror: [Errno 11001] getaddrinfo failed
[2024-06-03 18:08:19,033] 3584 cassandra.cluster - WARNING -[control connection] Error connecting to e4d5a3c1-e93d-4762-b366-9ba2252f22f5-eu-west-1.db.astra.datastax.com:29042:678e6a1d-e5b1-3cba-b949-7bfaf823957f:
Traceback (most recent call last):
  File "C:\Users\DELL\anaconda3\envs\pythonProject5\lib\site-packages\cassandra\cluster.py", line 3577, in _reconnect_internal
    return self._try_connect(host)
  File "C:\Users\DELL\anaconda3\envs\pythonProject5\lib\site-packages\cassandra\cluster.py", line 3599, in _try_connect
    connection = self._cluster.connection_factory(host.endpoint, is_control_connection=True)
  File "C:\Users\DELL\anaconda3\envs\pythonProject5\lib\site-packages\cassandra\cluster.py", line 1670, in connection_factory
    return self.connection_class.factory(endpoint, self.connect_timeout, *args, **kwargs)
  File "C:\Users\DELL\anaconda3\envs\pythonProject5\lib\site-packages\cassandra\connection.py", line 846, in factory
    conn = cls(endpoint, *args, **kwargs)
  File "C:\Users\DELL\anaconda3\envs\pythonProject5\lib\site-packages\cassandra\io\asyncorereactor.py", line 354, in __init__
    self._connect_socket()
  File "C:\Users\DELL\anaconda3\envs\pythonProject5\lib\site-packages\cassandra\connection.py", line 925, in _connect_socket
    addresses = self._get_socket_addresses()
  File "C:\Users\DELL\anaconda3\envs\pythonProject5\lib\site-packages\cassandra\connection.py", line 912, in _get_socket_addresses
    address, port = self.endpoint.resolve()
  File "C:\Users\DELL\anaconda3\envs\pythonProject5\lib\site-packages\cassandra\connection.py", line 271, in resolve
    socket.AF_UNSPEC, socket.SOCK_STREAM)
  File "C:\Users\DELL\anaconda3\envs\pythonProject5\lib\socket.py", line 752, in getaddrinfo
    for res in _socket.getaddrinfo(host, port, family, type, proto, flags):
socket.gaierror: [Errno 11001] getaddrinfo failed
[2024-06-03 18:08:19,035] 3584 cassandra.cluster - WARNING -[control connection] Error connecting to e4d5a3c1-e93d-4762-b366-9ba2252f22f5-eu-west-1.db.astra.datastax.com:29042:0669df0f-031f-383e-b452-67a9679bbc6a:
Traceback (most recent call last):
  File "C:\Users\DELL\anaconda3\envs\pythonProject5\lib\site-packages\cassandra\cluster.py", line 3577, in _reconnect_internal
    return self._try_connect(host)
  File "C:\Users\DELL\anaconda3\envs\pythonProject5\lib\site-packages\cassandra\cluster.py", line 3599, in _try_connect
    connection = self._cluster.connection_factory(host.endpoint, is_control_connection=True)
  File "C:\Users\DELL\anaconda3\envs\pythonProject5\lib\site-packages\cassandra\cluster.py", line 1670, in connection_factory
    return self.connection_class.factory(endpoint, self.connect_timeout, *args, **kwargs)
  File "C:\Users\DELL\anaconda3\envs\pythonProject5\lib\site-packages\cassandra\connection.py", line 846, in factory
    conn = cls(endpoint, *args, **kwargs)
  File "C:\Users\DELL\anaconda3\envs\pythonProject5\lib\site-packages\cassandra\io\asyncorereactor.py", line 354, in __init__
    self._connect_socket()
  File "C:\Users\DELL\anaconda3\envs\pythonProject5\lib\site-packages\cassandra\connection.py", line 925, in _connect_socket
    addresses = self._get_socket_addresses()
  File "C:\Users\DELL\anaconda3\envs\pythonProject5\lib\site-packages\cassandra\connection.py", line 912, in _get_socket_addresses
    address, port = self.endpoint.resolve()
  File "C:\Users\DELL\anaconda3\envs\pythonProject5\lib\site-packages\cassandra\connection.py", line 271, in resolve
    socket.AF_UNSPEC, socket.SOCK_STREAM)
  File "C:\Users\DELL\anaconda3\envs\pythonProject5\lib\socket.py", line 752, in getaddrinfo
    for res in _socket.getaddrinfo(host, port, family, type, proto, flags):
socket.gaierror: [Errno 11001] getaddrinfo failed
[2024-06-03 18:08:19,037] 3584 cassandra.cluster - WARNING -[control connection] Error connecting to e4d5a3c1-e93d-4762-b366-9ba2252f22f5-eu-west-1.db.astra.datastax.com:29042:0669df0f-031f-383e-b452-67a9679bbc6a:
Traceback (most recent call last):
  File "C:\Users\DELL\anaconda3\envs\pythonProject5\lib\site-packages\cassandra\cluster.py", line 3577, in _reconnect_internal
    return self._try_connect(host)
  File "C:\Users\DELL\anaconda3\envs\pythonProject5\lib\site-packages\cassandra\cluster.py", line 3599, in _try_connect
    connection = self._cluster.connection_factory(host.endpoint, is_control_connection=True)
  File "C:\Users\DELL\anaconda3\envs\pythonProject5\lib\site-packages\cassandra\cluster.py", line 1670, in connection_factory
    return self.connection_class.factory(endpoint, self.connect_timeout, *args, **kwargs)
  File "C:\Users\DELL\anaconda3\envs\pythonProject5\lib\site-packages\cassandra\connection.py", line 846, in factory
    conn = cls(endpoint, *args, **kwargs)
  File "C:\Users\DELL\anaconda3\envs\pythonProject5\lib\site-packages\cassandra\io\asyncorereactor.py", line 354, in __init__
    self._connect_socket()
  File "C:\Users\DELL\anaconda3\envs\pythonProject5\lib\site-packages\cassandra\connection.py", line 925, in _connect_socket
    addresses = self._get_socket_addresses()
  File "C:\Users\DELL\anaconda3\envs\pythonProject5\lib\site-packages\cassandra\connection.py", line 912, in _get_socket_addresses
    address, port = self.endpoint.resolve()
  File "C:\Users\DELL\anaconda3\envs\pythonProject5\lib\site-packages\cassandra\connection.py", line 271, in resolve
    socket.AF_UNSPEC, socket.SOCK_STREAM)
  File "C:\Users\DELL\anaconda3\envs\pythonProject5\lib\socket.py", line 752, in getaddrinfo
    for res in _socket.getaddrinfo(host, port, family, type, proto, flags):
socket.gaierror: [Errno 11001] getaddrinfo failed
[2024-06-03 18:08:19,039] 3584 cassandra.cluster - WARNING -[control connection] Error connecting to e4d5a3c1-e93d-4762-b366-9ba2252f22f5-eu-west-1.db.astra.datastax.com:29042:9e3a5bee-3d95-3bf7-90f5-09bd2177324b:
Traceback (most recent call last):
  File "C:\Users\DELL\anaconda3\envs\pythonProject5\lib\site-packages\cassandra\cluster.py", line 3577, in _reconnect_internal
    return self._try_connect(host)
  File "C:\Users\DELL\anaconda3\envs\pythonProject5\lib\site-packages\cassandra\cluster.py", line 3599, in _try_connect
    connection = self._cluster.connection_factory(host.endpoint, is_control_connection=True)
  File "C:\Users\DELL\anaconda3\envs\pythonProject5\lib\site-packages\cassandra\cluster.py", line 1670, in connection_factory
    return self.connection_class.factory(endpoint, self.connect_timeout, *args, **kwargs)
  File "C:\Users\DELL\anaconda3\envs\pythonProject5\lib\site-packages\cassandra\connection.py", line 846, in factory
    conn = cls(endpoint, *args, **kwargs)
  File "C:\Users\DELL\anaconda3\envs\pythonProject5\lib\site-packages\cassandra\io\asyncorereactor.py", line 354, in __init__
    self._connect_socket()
  File "C:\Users\DELL\anaconda3\envs\pythonProject5\lib\site-packages\cassandra\connection.py", line 925, in _connect_socket
    addresses = self._get_socket_addresses()
  File "C:\Users\DELL\anaconda3\envs\pythonProject5\lib\site-packages\cassandra\connection.py", line 912, in _get_socket_addresses
    address, port = self.endpoint.resolve()
  File "C:\Users\DELL\anaconda3\envs\pythonProject5\lib\site-packages\cassandra\connection.py", line 271, in resolve
    socket.AF_UNSPEC, socket.SOCK_STREAM)
  File "C:\Users\DELL\anaconda3\envs\pythonProject5\lib\socket.py", line 752, in getaddrinfo
    for res in _socket.getaddrinfo(host, port, family, type, proto, flags):
socket.gaierror: [Errno 11001] getaddrinfo failed
[2024-06-03 18:08:19,041] 3584 cassandra.cluster - WARNING -[control connection] Error connecting to e4d5a3c1-e93d-4762-b366-9ba2252f22f5-eu-west-1.db.astra.datastax.com:29042:9e3a5bee-3d95-3bf7-90f5-09bd2177324b:
Traceback (most recent call last):
  File "C:\Users\DELL\anaconda3\envs\pythonProject5\lib\site-packages\cassandra\cluster.py", line 3577, in _reconnect_internal
    return self._try_connect(host)
  File "C:\Users\DELL\anaconda3\envs\pythonProject5\lib\site-packages\cassandra\cluster.py", line 3599, in _try_connect
    connection = self._cluster.connection_factory(host.endpoint, is_control_connection=True)
  File "C:\Users\DELL\anaconda3\envs\pythonProject5\lib\site-packages\cassandra\cluster.py", line 1670, in connection_factory
    return self.connection_class.factory(endpoint, self.connect_timeout, *args, **kwargs)
  File "C:\Users\DELL\anaconda3\envs\pythonProject5\lib\site-packages\cassandra\connection.py", line 846, in factory
    conn = cls(endpoint, *args, **kwargs)
  File "C:\Users\DELL\anaconda3\envs\pythonProject5\lib\site-packages\cassandra\io\asyncorereactor.py", line 354, in __init__
    self._connect_socket()
  File "C:\Users\DELL\anaconda3\envs\pythonProject5\lib\site-packages\cassandra\connection.py", line 925, in _connect_socket
    addresses = self._get_socket_addresses()
  File "C:\Users\DELL\anaconda3\envs\pythonProject5\lib\site-packages\cassandra\connection.py", line 912, in _get_socket_addresses
    address, port = self.endpoint.resolve()
  File "C:\Users\DELL\anaconda3\envs\pythonProject5\lib\site-packages\cassandra\connection.py", line 271, in resolve
    socket.AF_UNSPEC, socket.SOCK_STREAM)
  File "C:\Users\DELL\anaconda3\envs\pythonProject5\lib\socket.py", line 752, in getaddrinfo
    for res in _socket.getaddrinfo(host, port, family, type, proto, flags):
socket.gaierror: [Errno 11001] getaddrinfo failed
[2024-06-03 18:08:19,043] 3584 cassandra.cluster - WARNING -[control connection] Error connecting to e4d5a3c1-e93d-4762-b366-9ba2252f22f5-eu-west-1.db.astra.datastax.com:29042:190dafab-6970-3a67-a21c-1226360de7dc:
Traceback (most recent call last):
  File "C:\Users\DELL\anaconda3\envs\pythonProject5\lib\site-packages\cassandra\cluster.py", line 3577, in _reconnect_internal
    return self._try_connect(host)
  File "C:\Users\DELL\anaconda3\envs\pythonProject5\lib\site-packages\cassandra\cluster.py", line 3599, in _try_connect
    connection = self._cluster.connection_factory(host.endpoint, is_control_connection=True)
  File "C:\Users\DELL\anaconda3\envs\pythonProject5\lib\site-packages\cassandra\cluster.py", line 1670, in connection_factory
    return self.connection_class.factory(endpoint, self.connect_timeout, *args, **kwargs)
  File "C:\Users\DELL\anaconda3\envs\pythonProject5\lib\site-packages\cassandra\connection.py", line 846, in factory
    conn = cls(endpoint, *args, **kwargs)
  File "C:\Users\DELL\anaconda3\envs\pythonProject5\lib\site-packages\cassandra\io\asyncorereactor.py", line 354, in __init__
    self._connect_socket()
  File "C:\Users\DELL\anaconda3\envs\pythonProject5\lib\site-packages\cassandra\connection.py", line 925, in _connect_socket
    addresses = self._get_socket_addresses()
  File "C:\Users\DELL\anaconda3\envs\pythonProject5\lib\site-packages\cassandra\connection.py", line 912, in _get_socket_addresses
    address, port = self.endpoint.resolve()
  File "C:\Users\DELL\anaconda3\envs\pythonProject5\lib\site-packages\cassandra\connection.py", line 271, in resolve
    socket.AF_UNSPEC, socket.SOCK_STREAM)
  File "C:\Users\DELL\anaconda3\envs\pythonProject5\lib\socket.py", line 752, in getaddrinfo
    for res in _socket.getaddrinfo(host, port, family, type, proto, flags):
socket.gaierror: [Errno 11001] getaddrinfo failed
[2024-06-03 18:08:19,045] 3584 cassandra.cluster - WARNING -[control connection] Error connecting to e4d5a3c1-e93d-4762-b366-9ba2252f22f5-eu-west-1.db.astra.datastax.com:29042:190dafab-6970-3a67-a21c-1226360de7dc:
Traceback (most recent call last):
  File "C:\Users\DELL\anaconda3\envs\pythonProject5\lib\site-packages\cassandra\cluster.py", line 3577, in _reconnect_internal
    return self._try_connect(host)
  File "C:\Users\DELL\anaconda3\envs\pythonProject5\lib\site-packages\cassandra\cluster.py", line 3599, in _try_connect
    connection = self._cluster.connection_factory(host.endpoint, is_control_connection=True)
  File "C:\Users\DELL\anaconda3\envs\pythonProject5\lib\site-packages\cassandra\cluster.py", line 1670, in connection_factory
    return self.connection_class.factory(endpoint, self.connect_timeout, *args, **kwargs)
  File "C:\Users\DELL\anaconda3\envs\pythonProject5\lib\site-packages\cassandra\connection.py", line 846, in factory
    conn = cls(endpoint, *args, **kwargs)
  File "C:\Users\DELL\anaconda3\envs\pythonProject5\lib\site-packages\cassandra\io\asyncorereactor.py", line 354, in __init__
    self._connect_socket()
  File "C:\Users\DELL\anaconda3\envs\pythonProject5\lib\site-packages\cassandra\connection.py", line 925, in _connect_socket
    addresses = self._get_socket_addresses()
  File "C:\Users\DELL\anaconda3\envs\pythonProject5\lib\site-packages\cassandra\connection.py", line 912, in _get_socket_addresses
    address, port = self.endpoint.resolve()
  File "C:\Users\DELL\anaconda3\envs\pythonProject5\lib\site-packages\cassandra\connection.py", line 271, in resolve
    socket.AF_UNSPEC, socket.SOCK_STREAM)
  File "C:\Users\DELL\anaconda3\envs\pythonProject5\lib\socket.py", line 752, in getaddrinfo
    for res in _socket.getaddrinfo(host, port, family, type, proto, flags):
socket.gaierror: [Errno 11001] getaddrinfo failed
[2024-06-03 18:08:19,047] 3584 cassandra.cluster - WARNING -[control connection] Error connecting to e4d5a3c1-e93d-4762-b366-9ba2252f22f5-eu-west-1.db.astra.datastax.com:29042:0750e59f-441b-37bb-b0a7-e097c5d725f7:
Traceback (most recent call last):
  File "C:\Users\DELL\anaconda3\envs\pythonProject5\lib\site-packages\cassandra\cluster.py", line 3577, in _reconnect_internal
    return self._try_connect(host)
  File "C:\Users\DELL\anaconda3\envs\pythonProject5\lib\site-packages\cassandra\cluster.py", line 3599, in _try_connect
    connection = self._cluster.connection_factory(host.endpoint, is_control_connection=True)
  File "C:\Users\DELL\anaconda3\envs\pythonProject5\lib\site-packages\cassandra\cluster.py", line 1670, in connection_factory
    return self.connection_class.factory(endpoint, self.connect_timeout, *args, **kwargs)
  File "C:\Users\DELL\anaconda3\envs\pythonProject5\lib\site-packages\cassandra\connection.py", line 846, in factory
    conn = cls(endpoint, *args, **kwargs)
  File "C:\Users\DELL\anaconda3\envs\pythonProject5\lib\site-packages\cassandra\io\asyncorereactor.py", line 354, in __init__
    self._connect_socket()
  File "C:\Users\DELL\anaconda3\envs\pythonProject5\lib\site-packages\cassandra\connection.py", line 925, in _connect_socket
    addresses = self._get_socket_addresses()
  File "C:\Users\DELL\anaconda3\envs\pythonProject5\lib\site-packages\cassandra\connection.py", line 912, in _get_socket_addresses
    address, port = self.endpoint.resolve()
  File "C:\Users\DELL\anaconda3\envs\pythonProject5\lib\site-packages\cassandra\connection.py", line 271, in resolve
    socket.AF_UNSPEC, socket.SOCK_STREAM)
  File "C:\Users\DELL\anaconda3\envs\pythonProject5\lib\socket.py", line 752, in getaddrinfo
    for res in _socket.getaddrinfo(host, port, family, type, proto, flags):
socket.gaierror: [Errno 11001] getaddrinfo failed
[2024-06-03 18:08:19,049] 3584 cassandra.cluster - WARNING -[control connection] Error connecting to e4d5a3c1-e93d-4762-b366-9ba2252f22f5-eu-west-1.db.astra.datastax.com:29042:0750e59f-441b-37bb-b0a7-e097c5d725f7:
Traceback (most recent call last):
  File "C:\Users\DELL\anaconda3\envs\pythonProject5\lib\site-packages\cassandra\cluster.py", line 3577, in _reconnect_internal
    return self._try_connect(host)
  File "C:\Users\DELL\anaconda3\envs\pythonProject5\lib\site-packages\cassandra\cluster.py", line 3599, in _try_connect
    connection = self._cluster.connection_factory(host.endpoint, is_control_connection=True)
  File "C:\Users\DELL\anaconda3\envs\pythonProject5\lib\site-packages\cassandra\cluster.py", line 1670, in connection_factory
    return self.connection_class.factory(endpoint, self.connect_timeout, *args, **kwargs)
  File "C:\Users\DELL\anaconda3\envs\pythonProject5\lib\site-packages\cassandra\connection.py", line 846, in factory
    conn = cls(endpoint, *args, **kwargs)
  File "C:\Users\DELL\anaconda3\envs\pythonProject5\lib\site-packages\cassandra\io\asyncorereactor.py", line 354, in __init__
    self._connect_socket()
  File "C:\Users\DELL\anaconda3\envs\pythonProject5\lib\site-packages\cassandra\connection.py", line 925, in _connect_socket
    addresses = self._get_socket_addresses()
  File "C:\Users\DELL\anaconda3\envs\pythonProject5\lib\site-packages\cassandra\connection.py", line 912, in _get_socket_addresses
    address, port = self.endpoint.resolve()
  File "C:\Users\DELL\anaconda3\envs\pythonProject5\lib\site-packages\cassandra\connection.py", line 271, in resolve
    socket.AF_UNSPEC, socket.SOCK_STREAM)
  File "C:\Users\DELL\anaconda3\envs\pythonProject5\lib\socket.py", line 752, in getaddrinfo
    for res in _socket.getaddrinfo(host, port, family, type, proto, flags):
socket.gaierror: [Errno 11001] getaddrinfo failed
[2024-06-03 18:08:19,051] 3584 cassandra.cluster - WARNING -[control connection] Error connecting to e4d5a3c1-e93d-4762-b366-9ba2252f22f5-eu-west-1.db.astra.datastax.com:29042:b4f6d9ed-0f1d-3f7a-82f1-a4a7ea4f84d4:
Traceback (most recent call last):
  File "C:\Users\DELL\anaconda3\envs\pythonProject5\lib\site-packages\cassandra\cluster.py", line 3577, in _reconnect_internal
    return self._try_connect(host)
  File "C:\Users\DELL\anaconda3\envs\pythonProject5\lib\site-packages\cassandra\cluster.py", line 3599, in _try_connect
    connection = self._cluster.connection_factory(host.endpoint, is_control_connection=True)
  File "C:\Users\DELL\anaconda3\envs\pythonProject5\lib\site-packages\cassandra\cluster.py", line 1670, in connection_factory
    return self.connection_class.factory(endpoint, self.connect_timeout, *args, **kwargs)
  File "C:\Users\DELL\anaconda3\envs\pythonProject5\lib\site-packages\cassandra\connection.py", line 846, in factory
    conn = cls(endpoint, *args, **kwargs)
  File "C:\Users\DELL\anaconda3\envs\pythonProject5\lib\site-packages\cassandra\io\asyncorereactor.py", line 354, in __init__
    self._connect_socket()
  File "C:\Users\DELL\anaconda3\envs\pythonProject5\lib\site-packages\cassandra\connection.py", line 925, in _connect_socket
    addresses = self._get_socket_addresses()
  File "C:\Users\DELL\anaconda3\envs\pythonProject5\lib\site-packages\cassandra\connection.py", line 912, in _get_socket_addresses
    address, port = self.endpoint.resolve()
  File "C:\Users\DELL\anaconda3\envs\pythonProject5\lib\site-packages\cassandra\connection.py", line 271, in resolve
    socket.AF_UNSPEC, socket.SOCK_STREAM)
  File "C:\Users\DELL\anaconda3\envs\pythonProject5\lib\socket.py", line 752, in getaddrinfo
    for res in _socket.getaddrinfo(host, port, family, type, proto, flags):
socket.gaierror: [Errno 11001] getaddrinfo failed
[2024-06-03 18:08:19,053] 3584 cassandra.cluster - WARNING -[control connection] Error connecting to e4d5a3c1-e93d-4762-b366-9ba2252f22f5-eu-west-1.db.astra.datastax.com:29042:b4f6d9ed-0f1d-3f7a-82f1-a4a7ea4f84d4:
Traceback (most recent call last):
  File "C:\Users\DELL\anaconda3\envs\pythonProject5\lib\site-packages\cassandra\cluster.py", line 3577, in _reconnect_internal
    return self._try_connect(host)
  File "C:\Users\DELL\anaconda3\envs\pythonProject5\lib\site-packages\cassandra\cluster.py", line 3599, in _try_connect
    connection = self._cluster.connection_factory(host.endpoint, is_control_connection=True)
  File "C:\Users\DELL\anaconda3\envs\pythonProject5\lib\site-packages\cassandra\cluster.py", line 1670, in connection_factory
    return self.connection_class.factory(endpoint, self.connect_timeout, *args, **kwargs)
  File "C:\Users\DELL\anaconda3\envs\pythonProject5\lib\site-packages\cassandra\connection.py", line 846, in factory
    conn = cls(endpoint, *args, **kwargs)
  File "C:\Users\DELL\anaconda3\envs\pythonProject5\lib\site-packages\cassandra\io\asyncorereactor.py", line 354, in __init__
    self._connect_socket()
  File "C:\Users\DELL\anaconda3\envs\pythonProject5\lib\site-packages\cassandra\connection.py", line 925, in _connect_socket
    addresses = self._get_socket_addresses()
  File "C:\Users\DELL\anaconda3\envs\pythonProject5\lib\site-packages\cassandra\connection.py", line 912, in _get_socket_addresses
    address, port = self.endpoint.resolve()
  File "C:\Users\DELL\anaconda3\envs\pythonProject5\lib\site-packages\cassandra\connection.py", line 271, in resolve
    socket.AF_UNSPEC, socket.SOCK_STREAM)
  File "C:\Users\DELL\anaconda3\envs\pythonProject5\lib\socket.py", line 752, in getaddrinfo
    for res in _socket.getaddrinfo(host, port, family, type, proto, flags):
socket.gaierror: [Errno 11001] getaddrinfo failed
[2024-06-03 18:08:19,057] 3584 cassandra.cluster - WARNING -[control connection] Error connecting to e4d5a3c1-e93d-4762-b366-9ba2252f22f5-eu-west-1.db.astra.datastax.com:29042:98a2cd7e-fa1b-3950-942e-42af495c4248:
Traceback (most recent call last):
  File "C:\Users\DELL\anaconda3\envs\pythonProject5\lib\site-packages\cassandra\cluster.py", line 3577, in _reconnect_internal
    return self._try_connect(host)
  File "C:\Users\DELL\anaconda3\envs\pythonProject5\lib\site-packages\cassandra\cluster.py", line 3599, in _try_connect
    connection = self._cluster.connection_factory(host.endpoint, is_control_connection=True)
  File "C:\Users\DELL\anaconda3\envs\pythonProject5\lib\site-packages\cassandra\cluster.py", line 1670, in connection_factory
    return self.connection_class.factory(endpoint, self.connect_timeout, *args, **kwargs)
  File "C:\Users\DELL\anaconda3\envs\pythonProject5\lib\site-packages\cassandra\connection.py", line 846, in factory
    conn = cls(endpoint, *args, **kwargs)
  File "C:\Users\DELL\anaconda3\envs\pythonProject5\lib\site-packages\cassandra\io\asyncorereactor.py", line 354, in __init__
    self._connect_socket()
  File "C:\Users\DELL\anaconda3\envs\pythonProject5\lib\site-packages\cassandra\connection.py", line 925, in _connect_socket
    addresses = self._get_socket_addresses()
  File "C:\Users\DELL\anaconda3\envs\pythonProject5\lib\site-packages\cassandra\connection.py", line 912, in _get_socket_addresses
    address, port = self.endpoint.resolve()
  File "C:\Users\DELL\anaconda3\envs\pythonProject5\lib\site-packages\cassandra\connection.py", line 271, in resolve
    socket.AF_UNSPEC, socket.SOCK_STREAM)
  File "C:\Users\DELL\anaconda3\envs\pythonProject5\lib\socket.py", line 752, in getaddrinfo
    for res in _socket.getaddrinfo(host, port, family, type, proto, flags):
socket.gaierror: [Errno 11001] getaddrinfo failed
[2024-06-03 18:08:23,329] 3863 cassandra.cluster - WARNING -Found multiple hosts with the same endpoint (e4d5a3c1-e93d-4762-b366-9ba2252f22f5-eu-west-1.db.astra.datastax.com:29042:678e6a1d-e5b1-3cba-b949-7bfaf823957f). Excluding peer 10.0.0.4
[2024-06-03 18:08:49,598] 3863 cassandra.cluster - WARNING -Found multiple hosts with the same endpoint (e4d5a3c1-e93d-4762-b366-9ba2252f22f5-eu-west-1.db.astra.datastax.com:29042:9e3a5bee-3d95-3bf7-90f5-09bd2177324b). Excluding peer 10.0.0.6
[2024-06-03 18:24:05,971] 212 apscheduler.scheduler - INFO -Scheduler has been shut down
