[2024-06-03 13:51:50,682] 181 apscheduler.scheduler - INFO -Scheduler started
[2024-06-03 13:52:18,672] 21 root - INFO -starting data ingestion
[2024-06-03 13:52:18,672] 27 root - INFO -Exporting data from casandra to feature store 
[2024-06-03 13:52:20,427] 1703 cassandra.cluster - WARNING -Downgrading core protocol version from 66 to 65 for e4d5a3c1-e93d-4762-b366-9ba2252f22f5-eu-west-1.db.astra.datastax.com:29042:00958fd0-af98-391f-9f51-7e3fe763da5c. To avoid this, it is best practice to explicitly set Cluster(protocol_version) to the version supported by your cluster. http://datastax.github.io/python-driver/api/cassandra/cluster.html#cassandra.cluster.Cluster.protocol_version
[2024-06-03 13:52:21,843] 1703 cassandra.cluster - WARNING -Downgrading core protocol version from 65 to 5 for e4d5a3c1-e93d-4762-b366-9ba2252f22f5-eu-west-1.db.astra.datastax.com:29042:00958fd0-af98-391f-9f51-7e3fe763da5c. To avoid this, it is best practice to explicitly set Cluster(protocol_version) to the version supported by your cluster. http://datastax.github.io/python-driver/api/cassandra/cluster.html#cassandra.cluster.Cluster.protocol_version
[2024-06-03 13:52:23,401] 1703 cassandra.cluster - WARNING -Downgrading core protocol version from 5 to 4 for e4d5a3c1-e93d-4762-b366-9ba2252f22f5-eu-west-1.db.astra.datastax.com:29042:00958fd0-af98-391f-9f51-7e3fe763da5c. To avoid this, it is best practice to explicitly set Cluster(protocol_version) to the version supported by your cluster. http://datastax.github.io/python-driver/api/cassandra/cluster.html#cassandra.cluster.Cluster.protocol_version
[2024-06-03 13:52:26,423] 292 cassandra.policies - INFO -Using datacenter 'eu-west-1' for DCAwareRoundRobinPolicy (via host 'e4d5a3c1-e93d-4762-b366-9ba2252f22f5-eu-west-1.db.astra.datastax.com:29042:00958fd0-af98-391f-9f51-7e3fe763da5c'); if incorrect, please specify a local_dc to the constructor, or limit contact points to local cluster nodes
[2024-06-03 13:52:26,424] 3863 cassandra.cluster - WARNING -Found multiple hosts with the same endpoint (e4d5a3c1-e93d-4762-b366-9ba2252f22f5-eu-west-1.db.astra.datastax.com:29042:00958fd0-af98-391f-9f51-7e3fe763da5c). Excluding peer 10.0.0.7
[2024-06-03 13:52:26,425] 2126 cassandra.cluster - INFO -Cassandra host e4d5a3c1-e93d-4762-b366-9ba2252f22f5-eu-west-1.db.astra.datastax.com:29042:00694036-11ec-39fb-8238-d79afd9b0e46 removed
[2024-06-03 13:52:31,661] 36 root - INFO -artifact-datainjection folder created 
[2024-06-03 13:52:31,671] 41 root - ERROR -Error occurred python script name [C:\Users\DELL\PycharmProjects\pythonProject5\src\pipeline\training_pipeline.py] line number [47] error message [Error occurred python script name [C:\Users\DELL\PycharmProjects\pythonProject5\src\pipeline\training_pipeline.py] line number [24] error message [Error occurred python script name [C:\Users\DELL\PycharmProjects\pythonProject5\src\components\data_ingestion.py] line number [46] error message ['DataIngestion' object has no attribute 'split_data_as_train_test']]]
Traceback (most recent call last):
  File "C:\Users\DELL\PycharmProjects\pythonProject5\src\components\data_ingestion.py", line 46, in initiate_data_ingestion
    self.split_data_as_train_test(dataframe=dataframe)
AttributeError: 'DataIngestion' object has no attribute 'split_data_as_train_test'

During handling of the above exception, another exception occurred:

Traceback (most recent call last):
  File "C:\Users\DELL\PycharmProjects\pythonProject5\src\pipeline\training_pipeline.py", line 24, in start_data_ingestion
    data_ingestion_artifact=data_ingestion.initiate_data_ingestion()
  File "C:\Users\DELL\PycharmProjects\pythonProject5\src\components\data_ingestion.py", line 53, in initiate_data_ingestion
    raise SensorException(e, sys)
src.exception.SensorException: Error occurred python script name [C:\Users\DELL\PycharmProjects\pythonProject5\src\components\data_ingestion.py] line number [46] error message ['DataIngestion' object has no attribute 'split_data_as_train_test']

During handling of the above exception, another exception occurred:

Traceback (most recent call last):
  File "C:\Users\DELL\PycharmProjects\pythonProject5\src\pipeline\training_pipeline.py", line 47, in run_pipeline
    data_ingestion_artifact: DataIngestionArtifact = self.start_data_ingestion()
  File "C:\Users\DELL\PycharmProjects\pythonProject5\src\pipeline\training_pipeline.py", line 30, in start_data_ingestion
    raise SensorException(e,sys)
src.exception.SensorException: Error occurred python script name [C:\Users\DELL\PycharmProjects\pythonProject5\src\pipeline\training_pipeline.py] line number [24] error message [Error occurred python script name [C:\Users\DELL\PycharmProjects\pythonProject5\src\components\data_ingestion.py] line number [46] error message ['DataIngestion' object has no attribute 'split_data_as_train_test']]

During handling of the above exception, another exception occurred:

Traceback (most recent call last):
  File "main.py", line 37, in trainRouteClient
    train_pipeline.run_pipeline()
  File "C:\Users\DELL\PycharmProjects\pythonProject5\src\pipeline\training_pipeline.py", line 51, in run_pipeline
    raise SensorException(e, sys)
src.exception.SensorException: Error occurred python script name [C:\Users\DELL\PycharmProjects\pythonProject5\src\pipeline\training_pipeline.py] line number [47] error message [Error occurred python script name [C:\Users\DELL\PycharmProjects\pythonProject5\src\pipeline\training_pipeline.py] line number [24] error message [Error occurred python script name [C:\Users\DELL\PycharmProjects\pythonProject5\src\components\data_ingestion.py] line number [46] error message ['DataIngestion' object has no attribute 'split_data_as_train_test']]]
[2024-06-03 13:52:31,675] 1745 main - ERROR -Exception on /train [GET]
Traceback (most recent call last):
  File "C:\Users\DELL\anaconda3\envs\pythonProject5\lib\site-packages\flask\app.py", line 2529, in wsgi_app
    response = self.full_dispatch_request()
  File "C:\Users\DELL\anaconda3\envs\pythonProject5\lib\site-packages\flask\app.py", line 1825, in full_dispatch_request
    rv = self.handle_user_exception(e)
  File "C:\Users\DELL\anaconda3\envs\pythonProject5\lib\site-packages\flask_cors\extension.py", line 178, in wrapped_function
    return cors_after_request(app.make_response(f(*args, **kwargs)))
  File "C:\Users\DELL\anaconda3\envs\pythonProject5\lib\site-packages\flask\app.py", line 1823, in full_dispatch_request
    rv = self.dispatch_request()
  File "C:\Users\DELL\anaconda3\envs\pythonProject5\lib\site-packages\flask\app.py", line 1799, in dispatch_request
    return self.ensure_sync(self.view_functions[rule.endpoint])(**view_args)
  File "C:\Users\DELL\anaconda3\envs\pythonProject5\lib\site-packages\flask_cors\decorator.py", line 130, in wrapped_function
    resp = make_response(f(*args, **kwargs))
  File "C:\Users\DELL\anaconda3\envs\pythonProject5\lib\site-packages\flask\helpers.py", line 209, in make_response
    return current_app.make_response(args)  # type: ignore
  File "C:\Users\DELL\anaconda3\envs\pythonProject5\lib\site-packages\flask\app.py", line 2139, in make_response
    f"The view function for {request.endpoint!r} did not"
TypeError: The view function for 'trainRouteClient' did not return a valid response. The function either returned None or ended without a return statement.
